Not Found: /favicon.ico
Unauthorized: /
Not Found: /favicon.ico
Not Found: /home
Admin is created at 2022-05-05 11:26:48.433932 hours!
Admin is created at 2022-05-05 11:28:42.047739 hours!
Manequin Category is updated at 2022-05-05 11:31:03.956883 hours!
Manequin Category is updated at 2022-05-05 11:31:04.008745 hours!
Unauthorized: /
Admin is created at 2022-05-05 11:32:51.306523 hours!
Internal Server Error: /admins
Traceback (most recent call last):
  File "C:\Users\userr\AppData\Local\Programs\Python\Python39\lib\site-packages\django\core\handlers\exception.py", line 55, in inner
    response = get_response(request)
  File "C:\Users\userr\AppData\Local\Programs\Python\Python39\lib\site-packages\django\utils\deprecation.py", line 133, in __call__
    response = self.process_request(request)
  File "C:\Users\userr\AppData\Local\Programs\Python\Python39\lib\site-packages\django\middleware\common.py", line 54, in process_request
    path = self.get_full_path_with_slash(request)
  File "C:\Users\userr\AppData\Local\Programs\Python\Python39\lib\site-packages\django\middleware\common.py", line 88, in get_full_path_with_slash
    raise RuntimeError(
RuntimeError: You called this URL via POST, but the URL doesn't end in a slash and you have APPEND_SLASH set. Django can't redirect to the slash URL while maintaining POST data. Change your form to point to 127.0.0.1:8000/admins/ (note the trailing slash), or set APPEND_SLASH=False in your Django settings.
Bad Request: /admins/
Bad Request: /admins/
Bad Request: /merchants/
Admin is created at 2022-05-05 11:53:00.194307 hours!
Admin is created at 2022-05-05 11:54:22.002401 hours!
Bad Request: /merchants/
Bad Request: /merchants/
Bad Request: /admins/
Bad Request: /admins/
Not Found: /api/token/'
Not Found: /api/token/'
Method Not Allowed: /api/token/
Unauthorized: /api/token/
Internal Server Error: /api/token/refresh
Traceback (most recent call last):
  File "C:\Users\userr\AppData\Local\Programs\Python\Python39\lib\site-packages\django\core\handlers\exception.py", line 55, in inner
    response = get_response(request)
  File "C:\Users\userr\AppData\Local\Programs\Python\Python39\lib\site-packages\django\utils\deprecation.py", line 133, in __call__
    response = self.process_request(request)
  File "C:\Users\userr\AppData\Local\Programs\Python\Python39\lib\site-packages\django\middleware\common.py", line 54, in process_request
    path = self.get_full_path_with_slash(request)
  File "C:\Users\userr\AppData\Local\Programs\Python\Python39\lib\site-packages\django\middleware\common.py", line 88, in get_full_path_with_slash
    raise RuntimeError(
RuntimeError: You called this URL via POST, but the URL doesn't end in a slash and you have APPEND_SLASH set. Django can't redirect to the slash URL while maintaining POST data. Change your form to point to 127.0.0.1:8000/api/token/refresh/ (note the trailing slash), or set APPEND_SLASH=False in your Django settings.
Bad Request: /api/token/refresh/
Unauthorized: /api/token/
Not Found: /main/login/
Internal Server Error: /api/token/verify
Traceback (most recent call last):
  File "C:\Users\userr\AppData\Local\Programs\Python\Python39\lib\site-packages\django\core\handlers\exception.py", line 55, in inner
    response = get_response(request)
  File "C:\Users\userr\AppData\Local\Programs\Python\Python39\lib\site-packages\django\utils\deprecation.py", line 133, in __call__
    response = self.process_request(request)
  File "C:\Users\userr\AppData\Local\Programs\Python\Python39\lib\site-packages\django\middleware\common.py", line 54, in process_request
    path = self.get_full_path_with_slash(request)
  File "C:\Users\userr\AppData\Local\Programs\Python\Python39\lib\site-packages\django\middleware\common.py", line 88, in get_full_path_with_slash
    raise RuntimeError(
RuntimeError: You called this URL via POST, but the URL doesn't end in a slash and you have APPEND_SLASH set. Django can't redirect to the slash URL while maintaining POST data. Change your form to point to 127.0.0.1:8000/api/token/verify/ (note the trailing slash), or set APPEND_SLASH=False in your Django settings.
Bad Request: /api/token/verify/
Bad Request: /api/token/verify/
Bad Request: /api/token/verify/
Bad Request: /api/token/verify/
Bad Request: /api/token/verify/
Bad Request: /api/token/verify/
Bad Request: /api/token/verify/
Bad Request: /api/token/verify/
Bad Request: /api/token/verify/
Bad Request: /api/token/verify/
Bad Request: /api/token/verify/
Bad Request: /api/token/verify/
Bad Request: /api/token/verify/
Bad Request: /api/token/verify/
Bad Request: /api/token/verify/
Internal Server Error: /admins/
Traceback (most recent call last):
  File "C:\Users\userr\AppData\Local\Programs\Python\Python39\lib\site-packages\django\core\handlers\exception.py", line 55, in inner
    response = get_response(request)
  File "C:\Users\userr\AppData\Local\Programs\Python\Python39\lib\site-packages\django\core\handlers\base.py", line 197, in _get_response
    response = wrapped_callback(request, *callback_args, **callback_kwargs)
  File "C:\Users\userr\AppData\Local\Programs\Python\Python39\lib\site-packages\django\views\decorators\csrf.py", line 54, in wrapped_view
    return view_func(*args, **kwargs)
  File "C:\Users\userr\AppData\Local\Programs\Python\Python39\lib\site-packages\rest_framework\viewsets.py", line 125, in view
    return self.dispatch(request, *args, **kwargs)
  File "C:\Users\userr\AppData\Local\Programs\Python\Python39\lib\site-packages\rest_framework\views.py", line 509, in dispatch
    response = self.handle_exception(exc)
  File "C:\Users\userr\AppData\Local\Programs\Python\Python39\lib\site-packages\rest_framework\views.py", line 469, in handle_exception
    self.raise_uncaught_exception(exc)
  File "C:\Users\userr\AppData\Local\Programs\Python\Python39\lib\site-packages\rest_framework\views.py", line 480, in raise_uncaught_exception
    raise exc
  File "C:\Users\userr\AppData\Local\Programs\Python\Python39\lib\site-packages\rest_framework\views.py", line 506, in dispatch
    response = handler(request, *args, **kwargs)
  File "C:\Users\userr\AppData\Local\Programs\Python\Python39\lib\site-packages\rest_framework\mixins.py", line 43, in list
    return self.get_paginated_response(serializer.data)
  File "C:\Users\userr\AppData\Local\Programs\Python\Python39\lib\site-packages\rest_framework\serializers.py", line 768, in data
    ret = super().data
  File "C:\Users\userr\AppData\Local\Programs\Python\Python39\lib\site-packages\rest_framework\serializers.py", line 253, in data
    self._data = self.to_representation(self.instance)
  File "C:\Users\userr\AppData\Local\Programs\Python\Python39\lib\site-packages\rest_framework\serializers.py", line 686, in to_representation
    return [
  File "C:\Users\userr\AppData\Local\Programs\Python\Python39\lib\site-packages\rest_framework\serializers.py", line 687, in <listcomp>
    self.child.to_representation(item) for item in iterable
  File "C:\Users\userr\AppData\Local\Programs\Python\Python39\lib\site-packages\rest_framework\serializers.py", line 507, in to_representation
    for field in fields:
  File "C:\Users\userr\AppData\Local\Programs\Python\Python39\lib\site-packages\rest_framework\serializers.py", line 368, in _readable_fields
    for field in self.fields.values():
  File "C:\Users\userr\AppData\Local\Programs\Python\Python39\lib\site-packages\django\utils\functional.py", line 49, in __get__
    res = instance.__dict__[self.name] = self.func(instance)
  File "C:\Users\userr\AppData\Local\Programs\Python\Python39\lib\site-packages\rest_framework\serializers.py", line 356, in fields
    for key, value in self.get_fields().items():
  File "C:\Users\userr\AppData\Local\Programs\Python\Python39\lib\site-packages\rest_framework\serializers.py", line 1052, in get_fields
    field_names = self.get_field_names(declared_fields, info)
  File "C:\Users\userr\AppData\Local\Programs\Python\Python39\lib\site-packages\rest_framework\serializers.py", line 1148, in get_field_names
    assert field_name in fields, (
AssertionError: The field 'user' was declared on serializer AdminSerializer, but has not been included in the 'fields' option.
Internal Server Error: /admins/
Traceback (most recent call last):
  File "C:\Users\userr\AppData\Local\Programs\Python\Python39\lib\site-packages\rest_framework\fields.py", line 457, in get_attribute
    return get_attribute(instance, self.source_attrs)
  File "C:\Users\userr\AppData\Local\Programs\Python\Python39\lib\site-packages\rest_framework\fields.py", line 97, in get_attribute
    instance = getattr(instance, attr)
AttributeError: 'AdminUser' object has no attribute 'user'

During handling of the above exception, another exception occurred:

Traceback (most recent call last):
  File "C:\Users\userr\AppData\Local\Programs\Python\Python39\lib\site-packages\django\core\handlers\exception.py", line 55, in inner
    response = get_response(request)
  File "C:\Users\userr\AppData\Local\Programs\Python\Python39\lib\site-packages\django\core\handlers\base.py", line 197, in _get_response
    response = wrapped_callback(request, *callback_args, **callback_kwargs)
  File "C:\Users\userr\AppData\Local\Programs\Python\Python39\lib\site-packages\django\views\decorators\csrf.py", line 54, in wrapped_view
    return view_func(*args, **kwargs)
  File "C:\Users\userr\AppData\Local\Programs\Python\Python39\lib\site-packages\rest_framework\viewsets.py", line 125, in view
    return self.dispatch(request, *args, **kwargs)
  File "C:\Users\userr\AppData\Local\Programs\Python\Python39\lib\site-packages\rest_framework\views.py", line 509, in dispatch
    response = self.handle_exception(exc)
  File "C:\Users\userr\AppData\Local\Programs\Python\Python39\lib\site-packages\rest_framework\views.py", line 469, in handle_exception
    self.raise_uncaught_exception(exc)
  File "C:\Users\userr\AppData\Local\Programs\Python\Python39\lib\site-packages\rest_framework\views.py", line 480, in raise_uncaught_exception
    raise exc
  File "C:\Users\userr\AppData\Local\Programs\Python\Python39\lib\site-packages\rest_framework\views.py", line 506, in dispatch
    response = handler(request, *args, **kwargs)
  File "C:\Users\userr\AppData\Local\Programs\Python\Python39\lib\site-packages\rest_framework\mixins.py", line 43, in list
    return self.get_paginated_response(serializer.data)
  File "C:\Users\userr\AppData\Local\Programs\Python\Python39\lib\site-packages\rest_framework\serializers.py", line 768, in data
    ret = super().data
  File "C:\Users\userr\AppData\Local\Programs\Python\Python39\lib\site-packages\rest_framework\serializers.py", line 253, in data
    self._data = self.to_representation(self.instance)
  File "C:\Users\userr\AppData\Local\Programs\Python\Python39\lib\site-packages\rest_framework\serializers.py", line 686, in to_representation
    return [
  File "C:\Users\userr\AppData\Local\Programs\Python\Python39\lib\site-packages\rest_framework\serializers.py", line 687, in <listcomp>
    self.child.to_representation(item) for item in iterable
  File "C:\Users\userr\AppData\Local\Programs\Python\Python39\lib\site-packages\rest_framework\serializers.py", line 509, in to_representation
    attribute = field.get_attribute(instance)
  File "C:\Users\userr\AppData\Local\Programs\Python\Python39\lib\site-packages\rest_framework\fields.py", line 490, in get_attribute
    raise type(exc)(msg)
AttributeError: Got AttributeError when attempting to get a value for field `user` on serializer `AdminSerializer`.
The serializer field might be named incorrectly and not match any attribute or key on the `AdminUser` instance.
Original exception text was: 'AdminUser' object has no attribute 'user'.
Internal Server Error: /admins/
Traceback (most recent call last):
  File "C:\Users\userr\AppData\Local\Programs\Python\Python39\lib\site-packages\django\core\handlers\exception.py", line 55, in inner
    response = get_response(request)
  File "C:\Users\userr\AppData\Local\Programs\Python\Python39\lib\site-packages\django\core\handlers\base.py", line 197, in _get_response
    response = wrapped_callback(request, *callback_args, **callback_kwargs)
  File "C:\Users\userr\AppData\Local\Programs\Python\Python39\lib\site-packages\django\views\decorators\csrf.py", line 54, in wrapped_view
    return view_func(*args, **kwargs)
  File "C:\Users\userr\AppData\Local\Programs\Python\Python39\lib\site-packages\rest_framework\viewsets.py", line 125, in view
    return self.dispatch(request, *args, **kwargs)
  File "C:\Users\userr\AppData\Local\Programs\Python\Python39\lib\site-packages\rest_framework\views.py", line 509, in dispatch
    response = self.handle_exception(exc)
  File "C:\Users\userr\AppData\Local\Programs\Python\Python39\lib\site-packages\rest_framework\views.py", line 469, in handle_exception
    self.raise_uncaught_exception(exc)
  File "C:\Users\userr\AppData\Local\Programs\Python\Python39\lib\site-packages\rest_framework\views.py", line 480, in raise_uncaught_exception
    raise exc
  File "C:\Users\userr\AppData\Local\Programs\Python\Python39\lib\site-packages\rest_framework\views.py", line 506, in dispatch
    response = handler(request, *args, **kwargs)
  File "C:\Users\userr\AppData\Local\Programs\Python\Python39\lib\site-packages\rest_framework\mixins.py", line 43, in list
    return self.get_paginated_response(serializer.data)
  File "C:\Users\userr\AppData\Local\Programs\Python\Python39\lib\site-packages\rest_framework\serializers.py", line 768, in data
    ret = super().data
  File "C:\Users\userr\AppData\Local\Programs\Python\Python39\lib\site-packages\rest_framework\serializers.py", line 253, in data
    self._data = self.to_representation(self.instance)
  File "C:\Users\userr\AppData\Local\Programs\Python\Python39\lib\site-packages\rest_framework\serializers.py", line 686, in to_representation
    return [
  File "C:\Users\userr\AppData\Local\Programs\Python\Python39\lib\site-packages\rest_framework\serializers.py", line 687, in <listcomp>
    self.child.to_representation(item) for item in iterable
  File "C:\Users\userr\AppData\Local\Programs\Python\Python39\lib\site-packages\rest_framework\serializers.py", line 507, in to_representation
    for field in fields:
  File "C:\Users\userr\AppData\Local\Programs\Python\Python39\lib\site-packages\rest_framework\serializers.py", line 368, in _readable_fields
    for field in self.fields.values():
  File "C:\Users\userr\AppData\Local\Programs\Python\Python39\lib\site-packages\django\utils\functional.py", line 49, in __get__
    res = instance.__dict__[self.name] = self.func(instance)
  File "C:\Users\userr\AppData\Local\Programs\Python\Python39\lib\site-packages\rest_framework\serializers.py", line 356, in fields
    for key, value in self.get_fields().items():
  File "C:\Users\userr\AppData\Local\Programs\Python\Python39\lib\site-packages\rest_framework\serializers.py", line 1076, in get_fields
    field_class, field_kwargs = self.build_field(
  File "C:\Users\userr\AppData\Local\Programs\Python\Python39\lib\site-packages\rest_framework\serializers.py", line 1222, in build_field
    return self.build_unknown_field(field_name, model_class)
  File "C:\Users\userr\AppData\Local\Programs\Python\Python39\lib\site-packages\rest_framework\serializers.py", line 1340, in build_unknown_field
    raise ImproperlyConfigured(
django.core.exceptions.ImproperlyConfigured: Field name `__all__` is not valid for model `AdminUser`.
Internal Server Error: /admins/
Traceback (most recent call last):
  File "C:\Users\userr\AppData\Local\Programs\Python\Python39\lib\site-packages\django\core\handlers\exception.py", line 55, in inner
    response = get_response(request)
  File "C:\Users\userr\AppData\Local\Programs\Python\Python39\lib\site-packages\django\core\handlers\base.py", line 197, in _get_response
    response = wrapped_callback(request, *callback_args, **callback_kwargs)
  File "C:\Users\userr\AppData\Local\Programs\Python\Python39\lib\site-packages\django\views\decorators\csrf.py", line 54, in wrapped_view
    return view_func(*args, **kwargs)
  File "C:\Users\userr\AppData\Local\Programs\Python\Python39\lib\site-packages\rest_framework\viewsets.py", line 125, in view
    return self.dispatch(request, *args, **kwargs)
  File "C:\Users\userr\AppData\Local\Programs\Python\Python39\lib\site-packages\rest_framework\views.py", line 509, in dispatch
    response = self.handle_exception(exc)
  File "C:\Users\userr\AppData\Local\Programs\Python\Python39\lib\site-packages\rest_framework\views.py", line 469, in handle_exception
    self.raise_uncaught_exception(exc)
  File "C:\Users\userr\AppData\Local\Programs\Python\Python39\lib\site-packages\rest_framework\views.py", line 480, in raise_uncaught_exception
    raise exc
  File "C:\Users\userr\AppData\Local\Programs\Python\Python39\lib\site-packages\rest_framework\views.py", line 506, in dispatch
    response = handler(request, *args, **kwargs)
  File "C:\Users\userr\AppData\Local\Programs\Python\Python39\lib\site-packages\rest_framework\mixins.py", line 43, in list
    return self.get_paginated_response(serializer.data)
  File "C:\Users\userr\AppData\Local\Programs\Python\Python39\lib\site-packages\rest_framework\serializers.py", line 768, in data
    ret = super().data
  File "C:\Users\userr\AppData\Local\Programs\Python\Python39\lib\site-packages\rest_framework\serializers.py", line 253, in data
    self._data = self.to_representation(self.instance)
  File "C:\Users\userr\AppData\Local\Programs\Python\Python39\lib\site-packages\rest_framework\serializers.py", line 686, in to_representation
    return [
  File "C:\Users\userr\AppData\Local\Programs\Python\Python39\lib\site-packages\rest_framework\serializers.py", line 687, in <listcomp>
    self.child.to_representation(item) for item in iterable
  File "C:\Users\userr\AppData\Local\Programs\Python\Python39\lib\site-packages\rest_framework\serializers.py", line 507, in to_representation
    for field in fields:
  File "C:\Users\userr\AppData\Local\Programs\Python\Python39\lib\site-packages\rest_framework\serializers.py", line 368, in _readable_fields
    for field in self.fields.values():
  File "C:\Users\userr\AppData\Local\Programs\Python\Python39\lib\site-packages\django\utils\functional.py", line 49, in __get__
    res = instance.__dict__[self.name] = self.func(instance)
  File "C:\Users\userr\AppData\Local\Programs\Python\Python39\lib\site-packages\rest_framework\serializers.py", line 356, in fields
    for key, value in self.get_fields().items():
  File "C:\Users\userr\AppData\Local\Programs\Python\Python39\lib\site-packages\rest_framework\serializers.py", line 1076, in get_fields
    field_class, field_kwargs = self.build_field(
  File "C:\Users\userr\AppData\Local\Programs\Python\Python39\lib\site-packages\rest_framework\serializers.py", line 1222, in build_field
    return self.build_unknown_field(field_name, model_class)
  File "C:\Users\userr\AppData\Local\Programs\Python\Python39\lib\site-packages\rest_framework\serializers.py", line 1340, in build_unknown_field
    raise ImproperlyConfigured(
django.core.exceptions.ImproperlyConfigured: Field name `__all__` is not valid for model `AdminUser`.
Internal Server Error: /admins/
Traceback (most recent call last):
  File "C:\Users\userr\AppData\Local\Programs\Python\Python39\lib\site-packages\rest_framework\fields.py", line 457, in get_attribute
    return get_attribute(instance, self.source_attrs)
  File "C:\Users\userr\AppData\Local\Programs\Python\Python39\lib\site-packages\rest_framework\fields.py", line 97, in get_attribute
    instance = getattr(instance, attr)
AttributeError: 'AdminUser' object has no attribute 'user'

During handling of the above exception, another exception occurred:

Traceback (most recent call last):
  File "C:\Users\userr\AppData\Local\Programs\Python\Python39\lib\site-packages\django\core\handlers\exception.py", line 55, in inner
    response = get_response(request)
  File "C:\Users\userr\AppData\Local\Programs\Python\Python39\lib\site-packages\django\core\handlers\base.py", line 197, in _get_response
    response = wrapped_callback(request, *callback_args, **callback_kwargs)
  File "C:\Users\userr\AppData\Local\Programs\Python\Python39\lib\site-packages\django\views\decorators\csrf.py", line 54, in wrapped_view
    return view_func(*args, **kwargs)
  File "C:\Users\userr\AppData\Local\Programs\Python\Python39\lib\site-packages\rest_framework\viewsets.py", line 125, in view
    return self.dispatch(request, *args, **kwargs)
  File "C:\Users\userr\AppData\Local\Programs\Python\Python39\lib\site-packages\rest_framework\views.py", line 509, in dispatch
    response = self.handle_exception(exc)
  File "C:\Users\userr\AppData\Local\Programs\Python\Python39\lib\site-packages\rest_framework\views.py", line 469, in handle_exception
    self.raise_uncaught_exception(exc)
  File "C:\Users\userr\AppData\Local\Programs\Python\Python39\lib\site-packages\rest_framework\views.py", line 480, in raise_uncaught_exception
    raise exc
  File "C:\Users\userr\AppData\Local\Programs\Python\Python39\lib\site-packages\rest_framework\views.py", line 506, in dispatch
    response = handler(request, *args, **kwargs)
  File "C:\Users\userr\AppData\Local\Programs\Python\Python39\lib\site-packages\rest_framework\mixins.py", line 43, in list
    return self.get_paginated_response(serializer.data)
  File "C:\Users\userr\AppData\Local\Programs\Python\Python39\lib\site-packages\rest_framework\serializers.py", line 768, in data
    ret = super().data
  File "C:\Users\userr\AppData\Local\Programs\Python\Python39\lib\site-packages\rest_framework\serializers.py", line 253, in data
    self._data = self.to_representation(self.instance)
  File "C:\Users\userr\AppData\Local\Programs\Python\Python39\lib\site-packages\rest_framework\serializers.py", line 686, in to_representation
    return [
  File "C:\Users\userr\AppData\Local\Programs\Python\Python39\lib\site-packages\rest_framework\serializers.py", line 687, in <listcomp>
    self.child.to_representation(item) for item in iterable
  File "C:\Users\userr\AppData\Local\Programs\Python\Python39\lib\site-packages\rest_framework\serializers.py", line 509, in to_representation
    attribute = field.get_attribute(instance)
  File "C:\Users\userr\AppData\Local\Programs\Python\Python39\lib\site-packages\rest_framework\fields.py", line 490, in get_attribute
    raise type(exc)(msg)
AttributeError: Got AttributeError when attempting to get a value for field `user` on serializer `AdminSerializer`.
The serializer field might be named incorrectly and not match any attribute or key on the `AdminUser` instance.
Original exception text was: 'AdminUser' object has no attribute 'user'.
Internal Server Error: /admins/
Traceback (most recent call last):
  File "C:\Users\userr\AppData\Local\Programs\Python\Python39\lib\site-packages\django\core\handlers\exception.py", line 55, in inner
    response = get_response(request)
  File "C:\Users\userr\AppData\Local\Programs\Python\Python39\lib\site-packages\django\core\handlers\base.py", line 197, in _get_response
    response = wrapped_callback(request, *callback_args, **callback_kwargs)
  File "C:\Users\userr\AppData\Local\Programs\Python\Python39\lib\site-packages\django\views\decorators\csrf.py", line 54, in wrapped_view
    return view_func(*args, **kwargs)
  File "C:\Users\userr\AppData\Local\Programs\Python\Python39\lib\site-packages\rest_framework\viewsets.py", line 125, in view
    return self.dispatch(request, *args, **kwargs)
  File "C:\Users\userr\AppData\Local\Programs\Python\Python39\lib\site-packages\rest_framework\views.py", line 509, in dispatch
    response = self.handle_exception(exc)
  File "C:\Users\userr\AppData\Local\Programs\Python\Python39\lib\site-packages\rest_framework\views.py", line 469, in handle_exception
    self.raise_uncaught_exception(exc)
  File "C:\Users\userr\AppData\Local\Programs\Python\Python39\lib\site-packages\rest_framework\views.py", line 480, in raise_uncaught_exception
    raise exc
  File "C:\Users\userr\AppData\Local\Programs\Python\Python39\lib\site-packages\rest_framework\views.py", line 506, in dispatch
    response = handler(request, *args, **kwargs)
  File "C:\Users\userr\AppData\Local\Programs\Python\Python39\lib\site-packages\rest_framework\mixins.py", line 43, in list
    return self.get_paginated_response(serializer.data)
  File "C:\Users\userr\AppData\Local\Programs\Python\Python39\lib\site-packages\rest_framework\serializers.py", line 768, in data
    ret = super().data
  File "C:\Users\userr\AppData\Local\Programs\Python\Python39\lib\site-packages\rest_framework\serializers.py", line 253, in data
    self._data = self.to_representation(self.instance)
  File "C:\Users\userr\AppData\Local\Programs\Python\Python39\lib\site-packages\rest_framework\serializers.py", line 686, in to_representation
    return [
  File "C:\Users\userr\AppData\Local\Programs\Python\Python39\lib\site-packages\rest_framework\serializers.py", line 687, in <listcomp>
    self.child.to_representation(item) for item in iterable
  File "C:\Users\userr\AppData\Local\Programs\Python\Python39\lib\site-packages\rest_framework\serializers.py", line 507, in to_representation
    for field in fields:
  File "C:\Users\userr\AppData\Local\Programs\Python\Python39\lib\site-packages\rest_framework\serializers.py", line 368, in _readable_fields
    for field in self.fields.values():
  File "C:\Users\userr\AppData\Local\Programs\Python\Python39\lib\site-packages\django\utils\functional.py", line 49, in __get__
    res = instance.__dict__[self.name] = self.func(instance)
  File "C:\Users\userr\AppData\Local\Programs\Python\Python39\lib\site-packages\rest_framework\serializers.py", line 356, in fields
    for key, value in self.get_fields().items():
  File "C:\Users\userr\AppData\Local\Programs\Python\Python39\lib\site-packages\rest_framework\serializers.py", line 1076, in get_fields
    field_class, field_kwargs = self.build_field(
  File "C:\Users\userr\AppData\Local\Programs\Python\Python39\lib\site-packages\rest_framework\serializers.py", line 1222, in build_field
    return self.build_unknown_field(field_name, model_class)
  File "C:\Users\userr\AppData\Local\Programs\Python\Python39\lib\site-packages\rest_framework\serializers.py", line 1340, in build_unknown_field
    raise ImproperlyConfigured(
django.core.exceptions.ImproperlyConfigured: Field name `__all__` is not valid for model `AdminUser`.
Internal Server Error: /admins/
Traceback (most recent call last):
  File "C:\Users\userr\AppData\Local\Programs\Python\Python39\lib\site-packages\django\core\handlers\exception.py", line 55, in inner
    response = get_response(request)
  File "C:\Users\userr\AppData\Local\Programs\Python\Python39\lib\site-packages\django\core\handlers\base.py", line 197, in _get_response
    response = wrapped_callback(request, *callback_args, **callback_kwargs)
  File "C:\Users\userr\AppData\Local\Programs\Python\Python39\lib\site-packages\django\views\decorators\csrf.py", line 54, in wrapped_view
    return view_func(*args, **kwargs)
  File "C:\Users\userr\AppData\Local\Programs\Python\Python39\lib\site-packages\rest_framework\viewsets.py", line 125, in view
    return self.dispatch(request, *args, **kwargs)
  File "C:\Users\userr\AppData\Local\Programs\Python\Python39\lib\site-packages\rest_framework\views.py", line 509, in dispatch
    response = self.handle_exception(exc)
  File "C:\Users\userr\AppData\Local\Programs\Python\Python39\lib\site-packages\rest_framework\views.py", line 469, in handle_exception
    self.raise_uncaught_exception(exc)
  File "C:\Users\userr\AppData\Local\Programs\Python\Python39\lib\site-packages\rest_framework\views.py", line 480, in raise_uncaught_exception
    raise exc
  File "C:\Users\userr\AppData\Local\Programs\Python\Python39\lib\site-packages\rest_framework\views.py", line 506, in dispatch
    response = handler(request, *args, **kwargs)
  File "C:\Users\userr\AppData\Local\Programs\Python\Python39\lib\site-packages\rest_framework\mixins.py", line 43, in list
    return self.get_paginated_response(serializer.data)
  File "C:\Users\userr\AppData\Local\Programs\Python\Python39\lib\site-packages\rest_framework\serializers.py", line 768, in data
    ret = super().data
  File "C:\Users\userr\AppData\Local\Programs\Python\Python39\lib\site-packages\rest_framework\serializers.py", line 253, in data
    self._data = self.to_representation(self.instance)
  File "C:\Users\userr\AppData\Local\Programs\Python\Python39\lib\site-packages\rest_framework\serializers.py", line 686, in to_representation
    return [
  File "C:\Users\userr\AppData\Local\Programs\Python\Python39\lib\site-packages\rest_framework\serializers.py", line 687, in <listcomp>
    self.child.to_representation(item) for item in iterable
  File "C:\Users\userr\AppData\Local\Programs\Python\Python39\lib\site-packages\rest_framework\serializers.py", line 507, in to_representation
    for field in fields:
  File "C:\Users\userr\AppData\Local\Programs\Python\Python39\lib\site-packages\rest_framework\serializers.py", line 368, in _readable_fields
    for field in self.fields.values():
  File "C:\Users\userr\AppData\Local\Programs\Python\Python39\lib\site-packages\django\utils\functional.py", line 49, in __get__
    res = instance.__dict__[self.name] = self.func(instance)
  File "C:\Users\userr\AppData\Local\Programs\Python\Python39\lib\site-packages\rest_framework\serializers.py", line 356, in fields
    for key, value in self.get_fields().items():
  File "C:\Users\userr\AppData\Local\Programs\Python\Python39\lib\site-packages\rest_framework\serializers.py", line 1076, in get_fields
    field_class, field_kwargs = self.build_field(
  File "C:\Users\userr\AppData\Local\Programs\Python\Python39\lib\site-packages\rest_framework\serializers.py", line 1222, in build_field
    return self.build_unknown_field(field_name, model_class)
  File "C:\Users\userr\AppData\Local\Programs\Python\Python39\lib\site-packages\rest_framework\serializers.py", line 1340, in build_unknown_field
    raise ImproperlyConfigured(
django.core.exceptions.ImproperlyConfigured: Field name `add_info` is not valid for model `AdminUser`.
Internal Server Error: /admins/
Traceback (most recent call last):
  File "C:\Users\userr\AppData\Local\Programs\Python\Python39\lib\site-packages\django\core\handlers\exception.py", line 55, in inner
    response = get_response(request)
  File "C:\Users\userr\AppData\Local\Programs\Python\Python39\lib\site-packages\django\core\handlers\base.py", line 197, in _get_response
    response = wrapped_callback(request, *callback_args, **callback_kwargs)
  File "C:\Users\userr\AppData\Local\Programs\Python\Python39\lib\site-packages\django\views\decorators\csrf.py", line 54, in wrapped_view
    return view_func(*args, **kwargs)
  File "C:\Users\userr\AppData\Local\Programs\Python\Python39\lib\site-packages\rest_framework\viewsets.py", line 125, in view
    return self.dispatch(request, *args, **kwargs)
  File "C:\Users\userr\AppData\Local\Programs\Python\Python39\lib\site-packages\rest_framework\views.py", line 509, in dispatch
    response = self.handle_exception(exc)
  File "C:\Users\userr\AppData\Local\Programs\Python\Python39\lib\site-packages\rest_framework\views.py", line 469, in handle_exception
    self.raise_uncaught_exception(exc)
  File "C:\Users\userr\AppData\Local\Programs\Python\Python39\lib\site-packages\rest_framework\views.py", line 480, in raise_uncaught_exception
    raise exc
  File "C:\Users\userr\AppData\Local\Programs\Python\Python39\lib\site-packages\rest_framework\views.py", line 506, in dispatch
    response = handler(request, *args, **kwargs)
  File "C:\Users\userr\AppData\Local\Programs\Python\Python39\lib\site-packages\rest_framework\mixins.py", line 43, in list
    return self.get_paginated_response(serializer.data)
  File "C:\Users\userr\AppData\Local\Programs\Python\Python39\lib\site-packages\rest_framework\serializers.py", line 768, in data
    ret = super().data
  File "C:\Users\userr\AppData\Local\Programs\Python\Python39\lib\site-packages\rest_framework\serializers.py", line 253, in data
    self._data = self.to_representation(self.instance)
  File "C:\Users\userr\AppData\Local\Programs\Python\Python39\lib\site-packages\rest_framework\serializers.py", line 686, in to_representation
    return [
  File "C:\Users\userr\AppData\Local\Programs\Python\Python39\lib\site-packages\rest_framework\serializers.py", line 687, in <listcomp>
    self.child.to_representation(item) for item in iterable
  File "C:\Users\userr\AppData\Local\Programs\Python\Python39\lib\site-packages\rest_framework\serializers.py", line 507, in to_representation
    for field in fields:
  File "C:\Users\userr\AppData\Local\Programs\Python\Python39\lib\site-packages\rest_framework\serializers.py", line 368, in _readable_fields
    for field in self.fields.values():
  File "C:\Users\userr\AppData\Local\Programs\Python\Python39\lib\site-packages\django\utils\functional.py", line 49, in __get__
    res = instance.__dict__[self.name] = self.func(instance)
  File "C:\Users\userr\AppData\Local\Programs\Python\Python39\lib\site-packages\rest_framework\serializers.py", line 356, in fields
    for key, value in self.get_fields().items():
  File "C:\Users\userr\AppData\Local\Programs\Python\Python39\lib\site-packages\rest_framework\serializers.py", line 1076, in get_fields
    field_class, field_kwargs = self.build_field(
  File "C:\Users\userr\AppData\Local\Programs\Python\Python39\lib\site-packages\rest_framework\serializers.py", line 1222, in build_field
    return self.build_unknown_field(field_name, model_class)
  File "C:\Users\userr\AppData\Local\Programs\Python\Python39\lib\site-packages\rest_framework\serializers.py", line 1340, in build_unknown_field
    raise ImproperlyConfigured(
django.core.exceptions.ImproperlyConfigured: Field name `add_info` is not valid for model `AdminUser`.
Internal Server Error: /admins/
Traceback (most recent call last):
  File "C:\Users\userr\AppData\Local\Programs\Python\Python39\lib\site-packages\rest_framework\fields.py", line 457, in get_attribute
    return get_attribute(instance, self.source_attrs)
  File "C:\Users\userr\AppData\Local\Programs\Python\Python39\lib\site-packages\rest_framework\fields.py", line 97, in get_attribute
    instance = getattr(instance, attr)
AttributeError: 'AdminUser' object has no attribute 'add_info'

During handling of the above exception, another exception occurred:

Traceback (most recent call last):
  File "C:\Users\userr\AppData\Local\Programs\Python\Python39\lib\site-packages\django\core\handlers\exception.py", line 55, in inner
    response = get_response(request)
  File "C:\Users\userr\AppData\Local\Programs\Python\Python39\lib\site-packages\django\core\handlers\base.py", line 197, in _get_response
    response = wrapped_callback(request, *callback_args, **callback_kwargs)
  File "C:\Users\userr\AppData\Local\Programs\Python\Python39\lib\site-packages\django\views\decorators\csrf.py", line 54, in wrapped_view
    return view_func(*args, **kwargs)
  File "C:\Users\userr\AppData\Local\Programs\Python\Python39\lib\site-packages\rest_framework\viewsets.py", line 125, in view
    return self.dispatch(request, *args, **kwargs)
  File "C:\Users\userr\AppData\Local\Programs\Python\Python39\lib\site-packages\rest_framework\views.py", line 509, in dispatch
    response = self.handle_exception(exc)
  File "C:\Users\userr\AppData\Local\Programs\Python\Python39\lib\site-packages\rest_framework\views.py", line 469, in handle_exception
    self.raise_uncaught_exception(exc)
  File "C:\Users\userr\AppData\Local\Programs\Python\Python39\lib\site-packages\rest_framework\views.py", line 480, in raise_uncaught_exception
    raise exc
  File "C:\Users\userr\AppData\Local\Programs\Python\Python39\lib\site-packages\rest_framework\views.py", line 506, in dispatch
    response = handler(request, *args, **kwargs)
  File "C:\Users\userr\AppData\Local\Programs\Python\Python39\lib\site-packages\rest_framework\mixins.py", line 43, in list
    return self.get_paginated_response(serializer.data)
  File "C:\Users\userr\AppData\Local\Programs\Python\Python39\lib\site-packages\rest_framework\serializers.py", line 768, in data
    ret = super().data
  File "C:\Users\userr\AppData\Local\Programs\Python\Python39\lib\site-packages\rest_framework\serializers.py", line 253, in data
    self._data = self.to_representation(self.instance)
  File "C:\Users\userr\AppData\Local\Programs\Python\Python39\lib\site-packages\rest_framework\serializers.py", line 686, in to_representation
    return [
  File "C:\Users\userr\AppData\Local\Programs\Python\Python39\lib\site-packages\rest_framework\serializers.py", line 687, in <listcomp>
    self.child.to_representation(item) for item in iterable
  File "C:\Users\userr\AppData\Local\Programs\Python\Python39\lib\site-packages\rest_framework\serializers.py", line 509, in to_representation
    attribute = field.get_attribute(instance)
  File "C:\Users\userr\AppData\Local\Programs\Python\Python39\lib\site-packages\rest_framework\fields.py", line 490, in get_attribute
    raise type(exc)(msg)
AttributeError: Got AttributeError when attempting to get a value for field `add_info` on serializer `AdminSerializer`.
The serializer field might be named incorrectly and not match any attribute or key on the `AdminUser` instance.
Original exception text was: 'AdminUser' object has no attribute 'add_info'.
Unauthorized: /
Unauthorized: /
